<?xml version="1.0" encoding="utf-8"?>
<robot name="Phillip">
	<link name="BLNsegment_joint"/>
	<link name="BPsegment_joint">
		<inertial>
			<mass value="0.11"/>
			<origin xyz="0 3.33729e-11 -0.0358" rpy="0 -0 0"/>
			<inertia ixx="0.000454" ixy="0" ixz="0" iyy="0.0003637" iyz="0" izz="0.0004191"/>
		</inertial>
	</link>
	<link name="BTsegment_joint">
		<inertial>
			<mass value="0.1"/>
			<origin xyz="0 3.33729e-11 -0.0336" rpy="0 -0 0"/>
			<inertia ixx="1.024" ixy="0" ixz="0" iyy="0.81796" iyz="0" izz="0.676"/>
		</inertial>
		<visual>
			<geometry>
				<mesh filename="models/collada/BTSegment_joint_visu.dae" scale="1 1 1"/>
			</geometry>
		</visual>
	</link>
	<link name="BUNsegment_joint">
		<inertial>
			<mass value="0.024"/>
			<origin xyz="0 3.33729e-11 -0.015" rpy="0 -0 0"/>
			<inertia ixx="0.0287585" ixy="0" ixz="0" iyy="0.0287585" iyz="0" izz="0.0139392"/>
		</inertial>
		<visual>
			<geometry>
				<mesh filename="models/collada/BUNsegment_joint_visu.dae" scale="1 1 1"/>
			</geometry>
		</visual>
	</link>
	<link name="Headsegment_joint">
		<inertial>
			<mass value="0.07"/>
			<origin xyz="0 3.33729e-11 -0.065" rpy="0 -0 0"/>
			<inertia ixx="0.612157" ixy="0" ixz="0" iyy="0.5733" iyz="0" izz="0.430612"/>
		</inertial>
		<visual>
			<geometry>
				<mesh filename="models/collada/HeadSegment_joint_visu.dae" scale="1 1 1"/>
			</geometry>
		</visual>
	</link>
	<link name="LAsegment_joint">
		<inertial>
			<mass value="0.04"/>
			<origin xyz="-2.75474e-15 1.04413e-08 0.1395" rpy="0 -0 0"/>
			<inertia ixx="0.237419" ixy="0" ixz="0" iyy="0.256481" iyz="0" izz="0.040572"/>
		</inertial>
		<visual>
			<geometry>
				<mesh filename="models/collada/LAsegment_joint_visu.dae" scale="1 1 1"/>
			</geometry>
		</visual>
	</link>
	<!-- <link name="LAy_joint"> -->
    <!-- <link name="LAAsegment_joint"> -->
		<!-- <visual> -->
			<!-- <geometry> -->
				<!-- <mesh filename="models/collada/LAy_joint_visu.dae" scale="1 1 1"/> -->
			<!-- </geometry> -->
		<!-- </visual> -->
	<!-- </link> -->
	<link name="LEsegment_joint">
		<inertial>
			<mass value="0.027"/>
			<origin xyz="-8.25728e-15 3.81383e-08 0.106" rpy="0 -0 0"/>
			<inertia ixx="0.0837755" ixy="0" ixz="0" iyy="0.0940772" iyz="0" izz="0.0287506"/>
		</inertial>
		<visual>
			<geometry>
				<mesh filename="models/collada/LEsegment_joint_visu.dae" scale="1 1 1"/>
			</geometry>
		</visual>
	</link>
	<link name="LFx_joint">
		<visual>
			<geometry>
				<mesh filename="models/collada/LFx_joint_visu.dae" scale="1 1 1"/>
			</geometry>
		</visual>
	</link>
	<link name="LHsegment_joint">
		<visual>
			<geometry>
				<mesh filename="models/collada/LHsegment_joint_visu.dae" scale="1 1 1"/>
			</geometry>
		</visual>
	</link>
	<link name="LKsegment_joint">
		<inertial>
			<mass value="0.14"/>
			<origin xyz="-2.75474e-15 1.04413e-08 0.1216" rpy="0 -0 0"/>
			<inertia ixx="3.0625" ixy="0" ixz="0" iyy="3.0625" iyz="0" izz="0.636804"/>
		</inertial>
		<visual>
			<geometry>
				<mesh filename="models/collada/LKsegment_joint_visu.dae" scale="1 1 1"/>
			</geometry>
		</visual>
	</link>
	<link name="LMrot_joint">
		<visual>
			<geometry>
				<mesh filename="models/collada/LMrot_joint_visu.dae" scale="1 1 1"/>
			</geometry>
		</visual>
	</link>
	<link name="LSCsegment_joint">
		<visual>
			<geometry>
				<mesh filename="models/collada/LSCsegment_joint_visu.dae" scale="1 1 1"/>
			</geometry>
		</visual>
	</link>
	<link name="LSsegment_joint">
		<inertial>
			<mass value="0.021"/>
			<origin xyz="0.01 4.16334e-17 0" rpy="0 -0 0"/>
			<inertia ixx="0.0298116" ixy="0" ixz="0" iyy="0.0063504" iyz="0" izz="0.0298116"/>
		</inertial>
		<visual>
			<geometry>
				<mesh filename="models/collada/LSsegment_joint_visu.dae" scale="1 1 1"/>
			</geometry>
		</visual>
	</link>
	<link name="LWsegment_joint">
		<inertial>
			<mass value="0.016"/>
			<origin xyz="-8.25728e-15 3.81383e-08 0.0826" rpy="0 -0 0"/>
			<inertia ixx="0.0319821" ixy="0" ixz="0" iyy="0.0340787" iyz="0" izz="0.0065229"/>
		</inertial>
		<visual>
			<geometry>
				<mesh filename="models/collada/LWsegment_joint_visu.dae" scale="1 1 1"/>
			</geometry>
		</visual>
	</link>
	<!-- <link name="LWWsegment_joint"> -->
	<!-- 	<visual> -->
	<!-- 		<geometry> -->
	<!-- 			<mesh filename="models/collada/LWy_joint_visu.dae" scale="1 1 1"/> -->
	<!-- 		</geometry> -->
	<!-- 	</visual> -->
	<!-- </link> -->
	<!-- <link name="LeftEyesegment_joint"> -->
	<!-- 	<visual> -->
	<!-- 		<geometry> -->
	<!-- 			<mesh filename="models/collada/LeftEyeSegmentY_joint_visu.dae" scale="1 1 1"/> -->
	<!-- 		</geometry> -->
	<!-- 	</visual> -->
	<!-- </link> -->
	<link name="LeftFootHeight_joint">
		<inertial>
			<mass value="0.013"/>
			<origin xyz="-8.35798e-11 0.025225 0.019" rpy="0 -0 0"/>
			<inertia ixx="0.0036504" ixy="0" ixz="0" iyy="0.0111794" iyz="0" izz="0.0096393"/>
		</inertial>
	</link>
	<link name="LeftHandsegment_joint">
		<inertial>
			<mass value="0.006"/>
			<origin xyz="-8.25728e-15 3.81383e-08 0.0534" rpy="0 -0 0"/>
			<inertia ixx="0.0021869" ixy="0" ixz="0" iyy="0.0033304" iyz="0" izz="0.001283"/>
		</inertial>
	</link>
	<link name="RAsegment_joint">
		<inertial>
			<mass value="0.04"/>
			<origin xyz="-3.88578e-16 1.04413e-08 0.1395" rpy="0 -0 0"/>
			<inertia ixx="0.237419" ixy="0" ixz="0" iyy="0.256481" iyz="0" izz="0.040572"/>
		</inertial>
		<visual>
			<geometry>
				<mesh filename="models/collada/RAsegment_joint_visu.dae" scale="1 1 1"/>
			</geometry>
		</visual>
	</link>
	<!-- <link name="RAAsegment_joint"> -->
	<!-- 	<visual> -->
	<!-- 		<geometry> -->
	<!-- 			<mesh filename="models/collada/RAy_joint_visu.dae" scale="1 1 1"/> -->
	<!-- 		</geometry> -->
	<!-- 	</visual> -->
	<!-- </link> -->
	<link name="REsegment_joint">
		<inertial>
			<mass value="0.027"/>
			<origin xyz="2.03848e-05 3.81383e-08 0.106" rpy="0 -0 0"/>
			<inertia ixx="0.0837755" ixy="0" ixz="0" iyy="0.0940772" iyz="0" izz="0.0287506"/>
		</inertial>
		<visual>
			<geometry>
				<mesh filename="models/collada/REsegment_joint_visu.dae" scale="1 1 1"/>
			</geometry>
		</visual>
	</link>
	<link name="RFsegment_joint">
		<visual>
			<geometry>
				<mesh filename="models/collada/RFx_joint_visu.dae" scale="1 1 1"/>
			</geometry>
		</visual>
	</link>
	<link name="RHsegment_joint">
		<visual>
			<geometry>
				<mesh filename="models/collada/RHsegment_joint_visu.dae" scale="1 1 1"/>
			</geometry>
		</visual>
	</link>
	<link name="RKsegment_joint">
		<inertial>
			<mass value="0.14"/>
			<origin xyz="4.56274e-05 1.04413e-08 0.1216" rpy="0 -0 0"/>
			<inertia ixx="3.0625" ixy="0" ixz="0" iyy="3.0625" iyz="0" izz="0.636804"/>
		</inertial>
		<visual>
			<geometry>
				<mesh filename="models/collada/RKsegment_joint_visu.dae" scale="1 1 1"/>
			</geometry>
		</visual>
	</link>
	<link name="RMrot_joint">
		<visual>
			<geometry>
				<mesh filename="models/collada/RMrot_joint_visu.dae" scale="1 1 1"/>
			</geometry>
		</visual>
	</link>
	<link name="RSCsegment_joint">
		<visual>
			<geometry>
				<mesh filename="models/collada/RSCsegment_joint_visu.dae" scale="1 1 1"/>
			</geometry>
		</visual>
	</link>
	<link name="RSsegment_joint">
		<inertial>
			<mass value="0.021"/>
			<origin xyz="-0.01 4.16334e-17 0" rpy="0 -0 0"/>
			<inertia ixx="0.0298116" ixy="0" ixz="0" iyy="0.0063504" iyz="0" izz="0.0298116"/>
		</inertial>
		<visual>
			<geometry>
				<mesh filename="models/collada/RSsegment_joint_visu.dae" scale="1 1 1"/>
			</geometry>
		</visual>
	</link>
	<link name="RWsegment_joint">
		<inertial>
			<mass value="0.016"/>
			<origin xyz="2.03848e-05 3.81383e-08 0.0826" rpy="0 -0 0"/>
			<inertia ixx="0.0319821" ixy="0" ixz="0" iyy="0.0340787" iyz="0" izz="0.0065229"/>
		</inertial>
		<visual>
			<geometry>
				<mesh filename="models/collada/RWsegment_joint_visu.dae" scale="1 1 1"/>
			</geometry>
		</visual>
	</link>
	<!-- <link name="RWy_joint"> -->
	<!-- 	<visual> -->
	<!-- 		<geometry> -->
	<!-- 			<mesh filename="models/collada/RWy_joint_visu.dae" scale="1 1 1"/> -->
	<!-- 		</geometry> -->
	<!-- 	</visual> -->
	<!-- </link> -->
	<link name="RightEyesegment_joint">
		<visual>
			<geometry>
				<mesh filename="models/collada/RightEyeSegmentY_joint_visu.dae" scale="1 1 1"/>
			</geometry>
		</visual>
	</link>
	<link name="RightFootHeight_joint">
		<inertial>
			<mass value="0.013"/>
			<origin xyz="-8.35776e-11 0.025225 0.019" rpy="0 -0 0"/>
			<inertia ixx="0.0036504" ixy="0" ixz="0" iyy="0.0111794" iyz="0" izz="0.0096393"/>
		</inertial>
	</link>
	<link name="RightFootLength_joint"/>
	<link name="RightHandsegment_joint">
		<inertial>
			<mass value="0.006"/>
			<origin xyz="2.03848e-05 3.81383e-08 0.0534" rpy="0 -0 0"/>
			<inertia ixx="0.0021869" ixy="0" ixz="0" iyy="0.0033304" iyz="0" izz="0.001283"/>
		</inertial>
	</link>
	<link name="collarsegment_joint">
		<inertial>
			<mass value="0.17"/>
			<origin xyz="0 3.33729e-11 -0.03384" rpy="0 -0 0"/>
			<inertia ixx="6.37245" ixy="0" ixz="0" iyy="5.09635" iyz="0" izz="4.22532"/>
		</inertial>
	</link>
	<link name="MidHeadsegment_joint"/>
	<link name="root"/>
	<link name="root_joint"/>
    <!-- Joints -->
	<joint name="BLNx_joint" type="revolute">
		<origin xyz="0 0 0.022" rpy="0 -0 0"/>
		<parent link="collarsegment_joint"/>
		<child link="BLNsegment_joint"/>
		<limit effort="100" velocity="1" lower="-0.785398" upper="0.261799"/>
	</joint>
	<joint name="BLNy_joint" type="revolute">
		<origin xyz="0 0 0.022" rpy="0 -0 0"/>
		<parent link="collarsegment_joint"/>
		<child link="BLNsegment_joint"/>
		<limit effort="100" velocity="1" lower="-0.349066" upper="0.349066"/>
	</joint>
	<joint name="BLNz_joint" type="revolute">
		<origin xyz="0 0 0.022" rpy="0 -0 0"/>
		<parent link="collarsegment_joint"/>
		<child link="BLNsegment_joint"/>
		<limit effort="100" velocity="1" lower="-0.261799" upper="0.261799"/>
	</joint>

	<joint name="BPx_joint" type="revolute">
		<parent link="root_joint"/>
		<child link="BPsegment_joint"/>
		<limit effort="100" velocity="1" lower="-0.872665" upper="0.610865"/>
	</joint>
	<joint name="BPy_joint" type="revolute">
		<origin xyz="0 0 0.04" rpy="0 -0 0"/>
		<parent link="root_joint"/>
		<child link="BPsegment_joint"/>
		<limit effort="100" velocity="1" lower="-0.349066" upper="0.349066"/>
	</joint>
	<joint name="BPz_joint" type="revolute">
		<origin xyz="0 0 0.04" rpy="0 -0 0"/>
		<parent link="root_joint"/>
		<child link="BPsegment_joint"/>
		<limit effort="100" velocity="1" lower="-0.785398" upper="0.785398"/>
	</joint>

	<joint name="BTx_joint" type="revolute">
		<origin xyz="0 0 0.06" rpy="0 -0 0"/>
		<parent link="BPsegment_joint"/>
		<child link="BTsegment_joint"/>
		<limit effort="100" velocity="1" lower="-0.610865" upper="0.471239"/>
	</joint>
	<joint name="BTy_joint" type="revolute">
		<origin xyz="0 0 0.06" rpy="0 -0 0"/>
		<parent link="BPsegment_joint"/>
		<child link="BTsegment_joint"/>
		<limit effort="100" velocity="1" lower="-0.349066" upper="0.349066"/>
	</joint>
	<joint name="BTz_joint" type="revolute">
		<origin xyz="0 0 0.06" rpy="0 -0 0"/>
		<parent link="BPsegment_joint"/>
		<child link="BTsegment_joint"/>
		<limit effort="100" velocity="1" lower="-0.628319" upper="0.628319"/>
	</joint>

	<joint name="BUNx_joint" type="revolute">
		<origin xyz="0 0 0.03" rpy="0 -0 0"/>
		<parent link="BLNsegment_joint"/>
		<child link="BUNsegment_joint"/>
		<limit effort="100" velocity="1" lower="-0.349066" upper="0.523599"/>
	</joint>
	<joint name="BUNy_joint" type="revolute">
		<origin xyz="0 0 0.03" rpy="0 -0 0"/>
		<parent link="BLNsegment_joint"/>
		<child link="BUNsegment_joint"/>
		<limit effort="100" velocity="1" lower="-0.261799" upper="0.261799"/>
	</joint>
	<joint name="BUNz_joint" type="revolute">
		<origin xyz="0 0 0.03" rpy="0 -0 0"/>
		<parent link="BLNsegment_joint"/>
		<child link="BUNsegment_joint"/>
		<limit effort="100" velocity="1" lower="-0.349066" upper="0.349066"/>
	</joint>

	<joint name="Headsegment_joint" type="fixed">
		<origin xyz="0 0 0.13" rpy="0 -0 0"/>
		<parent link="BUNsegment_joint"/>
		<child link="Headsegment_joint"/>
	</joint>

	<joint name="LAx_joint" type="revolute">
		<origin xyz="0 0 -0.246" rpy="0 -0 0"/>
		<parent link="LAsegment_joint"/>
		<child link="LAsegment_joint"/>
		<limit effort="100" velocity="1" lower="-0.698132" upper="0.523599"/>
	</joint>
	<joint name="LAy_joint" type="revolute">
		<origin xyz="0 0 -0.246" rpy="0 -0 0"/>
		<parent link="LKsegment_joint"/>
		<child link="LAsegment_joint"/>
		<limit effort="100" velocity="1" lower="-0.349066" upper="0.349066"/>
	</joint>
	<joint name="LAz_joint" type="revolute">
		<origin xyz="0 0 -0.246" rpy="0 -0 0"/>
		<parent link="LKsegment_joint"/>
		<child link="LAsegment_joint"/>
		<limit effort="100" velocity="1" lower="-0.523599" upper="0.523599"/>
	</joint>

	<joint name="LEx_joint" type="revolute">
		<origin xyz="0 0 -0.188" rpy="0 -0 0"/>
		<parent link="LSsegment_joint"/>
		<child link="LEsegment_joint"/>
		<limit effort="100" velocity="1" lower="0" upper="2.79253"/>
	</joint>
	<joint name="LEz_joint" type="revolute">
		<origin xyz="0 0 -0.188" rpy="0 -0 0"/>
		<parent link="LSsegment_joint"/>
		<child link="LEsegment_joint"/>
		<limit effort="100" velocity="1" lower="-1.5708" upper="1.5708"/>
	</joint>

	<joint name="LFx_joint" type="revolute">
		<origin xyz="-0.0088 0.0537 -0.0144" rpy="-0.261799306 -0 0.15707922"/>
		<parent link="LMrot_joint"/>
		<child link="LFx_joint"/>
		<limit effort="100" velocity="1" lower="-0.785398" upper="1.5708"/>
	</joint>

	<joint name="LHx_joint" type="revolute">
		<origin xyz="-0.052 0 0" rpy="0 -0 0"/>
		<parent link="root_joint"/>
		<child link="LHsegment_joint"/>
		<limit effort="100" velocity="1" lower="-0.872665" upper="1.65806"/>
	</joint>
	<joint name="LHy_joint" type="revolute">
		<origin xyz="-0.052 0 0" rpy="0 -0 0"/>
		<parent link="root_joint"/>
		<child link="LHsegment_joint"/>
		<limit effort="100" velocity="1" lower="-0.349066" upper="1.13446"/>
	</joint>
	<joint name="LHz_joint" type="revolute">
		<origin xyz="-0.052 0 0" rpy="0 -0 0"/>
		<parent link="root_joint"/>
		<child link="LHsegment_joint"/>
		<limit effort="100" velocity="1" lower="-0.785398" upper="0.785398"/>
	</joint>

	<joint name="LKx_joint" type="revolute">
		<origin xyz="0 0 -0.245" rpy="0 -0 0"/>
		<parent link="LHsegment_joint"/>
		<child link="LKsegment_joint"/>
		<limit effort="100" velocity="1" lower="-2.26893" upper="0"/>
	</joint>

	<joint name="LMrot_joint" type="revolute">
		<origin xyz="0.0006 0.0238 -0.0187" rpy="0.261799306 -0 -0.15707922"/>
		<axis xyz="0 1 0"/>
		<parent link="LAsegment_joint"/>
		<child link="LMrot_joint"/>
		<limit effort="100" velocity="1" lower="-0.261799" upper="0.261799"/>
	</joint>

	<joint name="LSCx_joint" type="revolute">
		<origin xyz="-0.087 0 0" rpy="0 -0 0"/>
		<parent link="collarsegment_joint"/>
		<child link="LSCsegment_joint"/>
		<limit effort="100" velocity="1" lower="0" upper="0"/>
	</joint>
	<joint name="LSCy_joint" type="revolute">
		<origin xyz="-0.087 0 0" rpy="0 -0 0"/>
		<parent link="collarsegment_joint"/>
		<child link="LSCsegment_joint"/>
		<limit effort="100" velocity="1" lower="-0.349066" upper="0.349066"/>
	</joint>
	<joint name="LSCz_joint" type="revolute">
		<origin xyz="-0.087 0 0" rpy="0 -0 0"/>
		<parent link="collarsegment_joint"/>
		<child link="LSCsegment_joint"/>
		<limit effort="100" velocity="1" lower="-0.349066" upper="0.349066"/>
	</joint>

	<joint name="LSx_joint" type="revolute">
		<origin xyz="-0.023 0 0" rpy="0 -0 0"/>
		<parent link="LSCsegment_joint"/>
		<child link="LSsegment_joint"/>
		<limit effort="100" velocity="1" lower="-1.22173" upper="3.31613"/>
	</joint>
	<joint name="LSy_joint" type="revolute">
		<origin xyz="-0.023 0 0" rpy="0 -0 0"/>
		<parent link="LSCsegment_joint"/>
		<child link="LSsegment_joint"/>
		<limit effort="100" velocity="1" lower="0" upper="2.79253"/>
	</joint>
	<joint name="LSz_joint" type="revolute">
		<origin xyz="-0.023 0 0" rpy="0 -0 0"/>
		<parent link="LSCsegment_joint"/>
		<child link="LSsegment_joint"/>
		<limit effort="100" velocity="1" lower="-1.22173" upper="1.0472"/>
	</joint>

	<joint name="LWx_joint" type="revolute">
		<origin xyz="0 0 -0.145" rpy="0 -0 0"/>
		<parent link="LEsegment_joint"/>
		<child link="LWsegment_joint"/>
		<limit effort="100" velocity="1" lower="-0.523599" upper="0.349066"/>
	</joint>
	<joint name="LWy_joint" type="revolute">
		<origin xyz="0 0 -0.145" rpy="0 -0 0"/>
		<parent link="LEsegment_joint"/>
		<child link="LWsegment_joint"/>
		<limit effort="100" velocity="1" lower="-1.22173" upper="1.5708"/>
	</joint>

	<joint name="LeftFootHeight_joint" type="fixed">
		<origin xyz="0 0 -0.039" rpy="0 -0 0"/>
		<parent link="LAsegment_joint"/>
		<child link="LeftFootHeight_joint"/>
	</joint>
	<joint name="LeftHandsegment_joint" type="fixed">
		<origin xyz="0 0 -0.108" rpy="0 -0 0"/>
		<parent link="LWsegment_joint"/>
		<child link="LeftHandsegment_joint"/>
	</joint>
	<joint name="MidHeadsegment_joint" type="fixed">
		<origin xyz="0 0 0.066" rpy="0 -0 0"/>
		<parent link="BUNsegment_joint"/>
		<child link="MidHeadsegment_joint"/>
	</joint>

	<joint name="RAx_joint" type="revolute">
		<origin xyz="0 0 -0.246" rpy="0 -0 0"/>
		<parent link="RKsegment_joint"/>
		<child link="RAsegment_joint"/>
		<limit effort="100" velocity="1" lower="-0.698132" upper="0.523599"/>
	</joint>
	<joint name="RAy_joint" type="revolute">
		<origin xyz="0 0 -0.246" rpy="0 -0 0"/>
		<parent link="RKsegment_joint"/>
		<child link="RAsegment_joint"/>
		<limit effort="100" velocity="1" lower="-0.349066" upper="0.349066"/>
	</joint>
	<joint name="RAz_joint" type="revolute">
		<origin xyz="0 0 -0.246" rpy="0 -0 0"/>
		<parent link="RKsegment_joint"/>
		<child link="RAsegment_joint"/>
		<limit effort="100" velocity="1" lower="-0.523599" upper="0.523599"/>
	</joint>

	<joint name="REx_joint" type="revolute">
		<origin xyz="0 0 -0.188" rpy="0 -0 0"/>
		<parent link="RSsegment_joint"/>
		<child link="REsegment_joint"/>
		<limit effort="100" velocity="1" lower="0" upper="2.79253"/>
	</joint>
	<joint name="REz_joint" type="revolute">
		<origin xyz="0 0 -0.188" rpy="0 -0 0"/>
		<parent link="RSsegment_joint"/>
		<child link="REsegment_joint"/>
		<limit effort="100" velocity="1" lower="-1.5708" upper="1.5708"/>
	</joint>

	<joint name="RFx_joint" type="revolute">
		<origin xyz="0.0088 0.0537 -0.0143922" rpy="-0.261799306 -0 -0.15707922"/>
		<parent link="RMrot_joint"/>
		<child link="RFsegment_joint"/>
		<limit effort="100" velocity="1" lower="-0.785398" upper="1.5708"/>
	</joint>

	<joint name="RHsegment_joint" type="fixed">
		<origin xyz="0.052 0 0" rpy="0 -0 0"/>
		<parent link="root_joint"/>
		<child link="RHsegment_joint"/>
	</joint>
	<joint name="RHx_joint" type="revolute">
		<origin xyz="0.052 0 0" rpy="0 -0 0"/>
		<parent link="root_joint"/>
		<child link="RHsegment_joint"/>
		<limit effort="100" velocity="1" lower="-0.872665" upper="1.65806"/>
	</joint>
	<joint name="RHy_joint" type="revolute">
		<origin xyz="0.052 0 0" rpy="0 -0 0"/>
		<parent link="root_joint"/>
		<child link="RHsegment_joint"/>
		<limit effort="100" velocity="1" lower="-1.13446" upper="0.349066"/>
	</joint>
	<joint name="RHz_joint" type="revolute">
		<origin xyz="0.052 0 0" rpy="0 -0 0"/>
		<parent link="root_joint"/>
		<child link="RHsegment_joint"/>
		<limit effort="100" velocity="1" lower="-0.785398" upper="0.785398"/>
	</joint>

	<joint name="RKx_joint" type="revolute">
		<origin xyz="0 0 -0.245" rpy="0 -0 0"/>
		<parent link="RHsegment_joint"/>
		<child link="RKsegment_joint"/>
		<limit effort="100" velocity="1" lower="-2.26893" upper="0"/>
	</joint>

	<joint name="RMrot_joint" type="revolute">
		<origin xyz="0.0006 0.0238 -0.0187" rpy="0.261799306 -0 0.15707922"/>
		<axis xyz="0 1 0"/>
		<parent link="RAsegment_joint"/>
		<child link="RMrot_joint"/>
		<limit effort="100" velocity="1" lower="-0.261799" upper="0.261799"/>
	</joint>

	<joint name="RSCx_joint" type="revolute">
		<origin xyz="0.087 0 0" rpy="0 -0 0"/>
		<parent link="collarsegment_joint"/>
		<child link="RSCsegment_joint"/>
		<limit effort="100" velocity="1" lower="0" upper="0"/>
	</joint>
	<joint name="RSCy_joint" type="revolute">
		<origin xyz="0.087 0 0" rpy="0 -0 0"/>
		<parent link="collarsegment_joint"/>
		<child link="RSCsegment_joint"/>
		<limit effort="100" velocity="1" lower="-0.349066" upper="0.349066"/>
	</joint>
	<joint name="RSCz_joint" type="revolute">
		<origin xyz="0.087 0 0" rpy="0 -0 0"/>
		<parent link="collarsegment_joint"/>
		<child link="RSCsegment_joint"/>
		<limit effort="100" velocity="1" lower="-0.349066" upper="0.349066"/>
	</joint>

	<joint name="RSx_joint" type="revolute">
		<origin xyz="0.023 0 0" rpy="0 -0 0"/>
		<parent link="RSCsegment_joint"/>
		<child link="RSsegment_joint"/>
		<limit effort="100" velocity="1" lower="-1.22173" upper="3.31613"/>
	</joint>
	<joint name="RSy_joint" type="revolute">
		<origin xyz="0.023 0 0" rpy="0 -0 0"/>
		<parent link="RSCsegment_joint"/>
		<child link="RSsegment_joint"/>
		<limit effort="100" velocity="1" lower="-2.79253" upper="0"/>
	</joint>
	<joint name="RSz_joint" type="revolute">
		<origin xyz="0.023 0 0" rpy="0 -0 0"/>
		<parent link="RSCsegment_joint"/>
		<child link="RSsegment_joint"/>
		<limit effort="100" velocity="1" lower="-1.0472" upper="1.22173"/>
	</joint>

	<joint name="RWx_joint" type="revolute">
		<origin xyz="0 0 -0.145" rpy="0 -0 0"/>
		<parent link="REsegment_joint"/>
		<child link="RWsegment_joint"/>
		<limit effort="100" velocity="1" lower="-0.523599" upper="0.349066"/>
	</joint>
	<joint name="RWy_joint" type="revolute">
		<origin xyz="0 0 -0.145" rpy="0 -0 0"/>
		<parent link="REsegment_joint"/>
		<child link="RWsegment_joint"/>
		<limit effort="100" velocity="1" lower="-1.5708" upper="1.22173"/>
	</joint>

	<joint name="RightEyesegment_joint" type="fixed">
		<origin xyz="0.015 0 0" rpy="0 -0 0"/>
		<parent link="MidHeadsegment_joint"/>
		<child link="RightEyesegment_joint"/>
	</joint>

	<joint name="RightFootHeight_joint" type="fixed">
		<origin xyz="0 0 -0.039" rpy="0 -0 0"/>
		<parent link="RAsegment_joint"/>
		<child link="RightFootHeight_joint"/>
	</joint>

	<joint name="RightFootLength_joint" type="fixed">
		<origin xyz="0 0.068 0" rpy="0 -0 0"/>
		<parent link="RightFootHeight_joint"/>
		<child link="RightFootLength_joint"/>
	</joint>

	<joint name="RightHandsegment_joint" type="fixed">
		<origin xyz="0 0 -0.108" rpy="0 -0 0"/>
		<parent link="RWsegment_joint"/>
		<child link="RightHandsegment_joint"/>
	</joint>

	<joint name="collarsegment_joint" type="fixed">
		<origin xyz="0 0 0.188" rpy="0 -0 0"/>
		<parent link="BTsegment_joint"/>
		<child link="collarsegment_joint"/>
	</joint>

	<joint name="root_joint" type="revolute">
		<axis xyz="0 0 1"/>
		<parent link="root"/>
		<child link="root_joint"/>
		<limit effort="100" velocity="1" lower="0" upper="0"/>
	</joint>
</robot>
